<sdf version='1.9'>
  <model name='6dof'>
    <link name='base_link'>
      <inertial>
        <pose>0.0708 0.05431751782424302 0.3314965688196442 0 0 0</pose>
        <mass>0.90000000000000002</mass>
        <inertia>
          <ixx>0.001485200000000006</ixx>
          <ixy>-7.7171288716954001e-10</ixy>
          <ixz>-1.005507704279762e-06</ixz>
          <iyy>0.001901700313254151</iyy>
          <iyz>4.1738878626268461e-07</iyz>
          <izz>0.0024559996867458459</izz>
        </inertia>
      </inertial>
      <collision name='base_link_fixed_joint_lump__body_collision'>
        <pose>0 0.05 0.3095 1.57 0 0</pose>
        <geometry>
          <mesh>
            <scale>0.001 0.001 0.001</scale>
            <uri>model://six_dof/meshes/chassisv2.stl</uri>
          </mesh>
        </geometry>
      </collision>
      <visual name='base_link_fixed_joint_lump__body_visual'>
        <pose>0 0.05 0.3095 1.57 0 0</pose>
        <geometry>
          <mesh>
            <scale>0.001 0.001 0.001</scale>
            <uri>model://six_dof/meshes/chassisv2.stl</uri>
          </mesh>
        </geometry>
        <material>
          <diffuse>0 0 1 1</diffuse>
          <ambient>0 0 1 1</ambient>
        </material>
      </visual>
    </link>
    <joint name='body_left_thigh_lateral' type='revolute'>
      <pose relative_to='base_link'>0.1 0.05 0.3095 1.571592652579834 1.268272058325985e-06 3.140000000504979</pose>
      <parent>base_link</parent>
      <child>intermediate_link_2</child>
      <axis>
        <xyz>0 0 1</xyz>
        <limit>
          <lower>-0.26000000000000001</lower>
          <upper>0.26000000000000001</upper>
          <effort>35</effort>
          <velocity>5.5</velocity>
        </limit>
        <dynamics>
          <damping>0.5</damping>
          <friction>0.69999999999999996</friction>
          <spring_reference>0</spring_reference>
          <spring_stiffness>0</spring_stiffness>
        </dynamics>
      </axis>
      <physics>
        <ode>
          <limit>
            <cfm>0</cfm>
            <erp>0.20000000000000001</erp>
          </limit>
        </ode>
      </physics>
      <joint>
        <dynamics damping='0.5' friction='0.7'/>
      </joint>
    </joint>
    <link name='intermediate_link_2'>
      <pose relative_to='body_left_thigh_lateral'>0 0 0 0 0 0</pose>
      <inertial>
        <pose>0 0 0 0 0 0</pose>
        <mass>0.0001</mass>
        <inertia>
          <ixx>1e-10</ixx>
          <ixy>0</ixy>
          <ixz>0</ixz>
          <iyy>1e-10</iyy>
          <iyz>0</iyz>
          <izz>1e-10</izz>
        </inertia>
      </inertial>
    </link>
    <joint name='body_left_thigh' type='revolute'>
      <pose relative_to='intermediate_link_2'>0 0 0 0 0 0</pose>
      <parent>intermediate_link_2</parent>
      <child>left_thigh</child>
      <axis>
        <xyz>1 0 0</xyz>
        <limit>
          <lower>-0.78000000000000003</lower>
          <upper>1.5700000000000001</upper>
          <effort>35</effort>
          <velocity>5.5</velocity>
        </limit>
        <dynamics>
          <damping>0.5</damping>
          <friction>0.69999999999999996</friction>
          <spring_reference>0</spring_reference>
          <spring_stiffness>0</spring_stiffness>
        </dynamics>
      </axis>
      <physics>
        <ode>
          <limit>
            <cfm>0</cfm>
            <erp>0.20000000000000001</erp>
          </limit>
        </ode>
      </physics>
      <joint>
        <dynamics damping='0.5' friction='0.7'/>
      </joint>
    </joint>
    <link name='left_thigh'>
      <pose relative_to='body_left_thigh'>0 0 0 0 0 0</pose>
      <inertial>
        <pose>-0.020539 -0.11748 -0.000178 0 0 0</pose>
        <mass>0.067626000000000006</mass>
        <inertia>
          <ixx>0.00015608000000000001</ixx>
          <ixy>3.5821660000000001e-06</ixy>
          <ixz>8.9158999999999998e-08</ixz>
          <iyy>1.3413745e-05</iyy>
          <iyz>1.5629600000000001e-07</iyz>
          <izz>0.00015954000000000001</izz>
        </inertia>
      </inertial>
      <collision name='left_thigh_collision'>
        <pose>0 0 0 0 0 0</pose>
        <geometry>
          <mesh>
            <scale>0.001 0.001 0.001</scale>
            <uri>model://six_dof/meshes/leftthighfixedv1.stl</uri>
          </mesh>
        </geometry>
      </collision>
      <visual name='left_thigh_visual'>
        <pose>0 0 0 0 0 0</pose>
        <geometry>
          <mesh>
            <scale>0.001 0.001 0.001</scale>
            <uri>model://six_dof/meshes/leftthighfixedv1.stl</uri>
          </mesh>
        </geometry>
        <material>
          <diffuse>0 1 1 1</diffuse>
          <ambient>0 1 1 1</ambient>
        </material>
      </visual>
    </link>
    <joint name='left_thigh_shin' type='revolute'>
      <pose relative_to='left_thigh'>-0.0425 -0.16 0 3.141592653589793 0.001592653589793114 3.141592653589793</pose>
      <parent>left_thigh</parent>
      <child>left_shin</child>
      <axis>
        <xyz>1 0 0</xyz>
        <limit>
          <lower>-1.04</lower>
          <upper>1.04</upper>
          <effort>35</effort>
          <velocity>5.5</velocity>
        </limit>
        <dynamics>
          <damping>0.5</damping>
          <friction>0.69999999999999996</friction>
          <spring_reference>0</spring_reference>
          <spring_stiffness>0</spring_stiffness>
        </dynamics>
      </axis>
      <physics>
        <ode>
          <limit>
            <cfm>0</cfm>
            <erp>0.20000000000000001</erp>
          </limit>
        </ode>
      </physics>
      <joint>
        <dynamics damping='0.5' friction='0.7'/>
      </joint>
    </joint>
    <link name='left_shin'>
      <pose relative_to='left_thigh_shin'>0 0 0 0 0 0</pose>
      <inertial>
        <pose>-0.02279 -0.05995 -6.999999999999999e-05 0 0 0</pose>
        <mass>0.014172000000000001</mass>
        <inertia>
          <ixx>0.0024608299999999998</ixx>
          <ixy>-1.6529999999999999e-05</ixy>
          <ixz>1.1999999999999999e-07</ixz>
          <iyy>0.00028524000000000003</iyy>
          <iyz>2.2999999999999999e-07</iyz>
          <izz>0.0027202900000000002</izz>
        </inertia>
      </inertial>
      <collision name='left_shin_collision'>
        <pose>0 0 0 0 0 0</pose>
        <geometry>
          <mesh>
            <scale>0.001 0.001 0.001</scale>
            <uri>model://six_dof/meshes/rightshinv3.stl</uri>
          </mesh>
        </geometry>
      </collision>
      <visual name='left_shin_visual'>
        <pose>0 0 0 0 0 0</pose>
        <geometry>
          <mesh>
            <scale>0.001 0.001 0.001</scale>
            <uri>model://six_dof/meshes/rightshinv3.stl</uri>
          </mesh>
        </geometry>
        <material>
          <diffuse>1 1 0 1</diffuse>
          <ambient>1 1 0 1</ambient>
        </material>
      </visual>
    </link>
    <joint name='left_shin_foot' type='revolute'>
      <pose relative_to='left_shin'>-0.02 -0.13 0 0 0 0</pose>
      <parent>left_shin</parent>
      <child>left_foot</child>
      <axis>
        <xyz>1 0 0</xyz>
        <limit>
          <lower>-0.52000000000000002</lower>
          <upper>0.52000000000000002</upper>
          <effort>35</effort>
          <velocity>5.5</velocity>
        </limit>
        <dynamics>
          <damping>0.69999999999999996</damping>
          <friction>1</friction>
          <spring_reference>0</spring_reference>
          <spring_stiffness>0</spring_stiffness>
        </dynamics>
      </axis>
      <physics>
        <ode>
          <limit>
            <cfm>0</cfm>
            <erp>0.20000000000000001</erp>
          </limit>
        </ode>
      </physics>
      <joint>
        <dynamics damping='0.7' friction='1.0'/>
      </joint>
    </joint>
    <link name='left_foot'>
      <pose relative_to='left_shin_foot'>0 0 0 0 0 0</pose>
      <inertial>
        <pose>-0.003 -0.011919 -9.8e-05 0 0 0</pose>
        <mass>0.022565999999999999</mass>
        <inertia>
          <ixx>9.6545799999999993e-06</ixx>
          <ixy>0</ixy>
          <ixz>3.0000000000000001e-12</ixz>
          <iyy>9.7001239999999995e-06</iyy>
          <iyz>7.7020799999999996e-07</iyz>
          <izz>1.471179e-06</izz>
        </inertia>
      </inertial>
      <collision name='left_foot_collision'>
        <pose>0 0 0 0 0 0</pose>
        <geometry>
          <mesh>
            <scale>0.001 0.001 0.001</scale>
            <uri>model://six_dof/meshes/footfixedv3.stl</uri>
          </mesh>
        </geometry>
      </collision>
      <visual name='left_foot_visual'>
        <pose>0 0 0 0 0 0</pose>
        <geometry>
          <mesh>
            <scale>0.001 0.001 0.001</scale>
            <uri>model://six_dof/meshes/footfixedv3.stl</uri>
          </mesh>
        </geometry>
        <material>
          <diffuse>0 1 0 1</diffuse>
          <ambient>0 1 0 1</ambient>
        </material>
      </visual>
    </link>
    <joint name='right_body_thigh_lateral' type='revolute'>
      <pose relative_to='base_link'>0 0.05 0.3095 1.57 0 0</pose>
      <parent>base_link</parent>
      <child>intermediate_link</child>
      <axis>
        <xyz>0 0 1</xyz>
        <limit>
          <lower>-0.26000000000000001</lower>
          <upper>0.26000000000000001</upper>
          <effort>35</effort>
          <velocity>5.5</velocity>
        </limit>
        <dynamics>
          <damping>0.5</damping>
          <friction>0.69999999999999996</friction>
          <spring_reference>0</spring_reference>
          <spring_stiffness>0</spring_stiffness>
        </dynamics>
      </axis>
      <physics>
        <ode>
          <limit>
            <cfm>0</cfm>
            <erp>0.20000000000000001</erp>
          </limit>
        </ode>
      </physics>
      <joint>
        <dynamics damping='0.5' friction='0.7'/>
      </joint>
    </joint>
    <link name='intermediate_link'>
      <pose relative_to='right_body_thigh_lateral'>0 0 0 0 0 0</pose>
      <inertial>
        <pose>0 0 0 0 0 0</pose>
        <mass>0.0001</mass>
        <inertia>
          <ixx>1e-10</ixx>
          <ixy>0</ixy>
          <ixz>0</ixz>
          <iyy>1e-10</iyy>
          <iyz>0</iyz>
          <izz>1e-10</izz>
        </inertia>
      </inertial>
    </link>
    <joint name='right_body_thigh' type='revolute'>
      <pose relative_to='intermediate_link'>0.041 0 0 0 0 0</pose>
      <parent>intermediate_link</parent>
      <child>right_thigh</child>
      <axis>
        <xyz>1 0 0</xyz>
        <limit>
          <lower>-1.5700000000000001</lower>
          <upper>0.78000000000000003</upper>
          <effort>35</effort>
          <velocity>5.5</velocity>
        </limit>
        <dynamics>
          <damping>0.5</damping>
          <friction>0.69999999999999996</friction>
          <spring_reference>0</spring_reference>
          <spring_stiffness>0</spring_stiffness>
        </dynamics>
      </axis>
      <physics>
        <ode>
          <limit>
            <cfm>0</cfm>
            <erp>0.20000000000000001</erp>
          </limit>
        </ode>
      </physics>
      <joint>
        <dynamics damping='0.5' friction='0.7'/>
      </joint>
    </joint>
    <link name='right_thigh'>
      <pose relative_to='right_body_thigh'>0 0 0 0 0 0</pose>
      <inertial>
        <pose>-0.020621 -0.116163 0.000182 0 0 0</pose>
        <mass>0.067538000000000001</mass>
        <inertia>
          <ixx>0.00015197999999999999</ixx>
          <ixy>3.3314009999999998e-06</ixy>
          <ixz>-8.9149e-08</ixz>
          <iyy>1.2751653999999999e-05</iyy>
          <iyz>-1.4226700000000001e-07</iyz>
          <izz>0.00015488000000000001</izz>
        </inertia>
      </inertial>
      <collision name='right_thigh_collision'>
        <pose>0 0 0 0 0 0</pose>
        <geometry>
          <mesh>
            <scale>0.001 0.001 0.001</scale>
            <uri>model://six_dof/meshes/rightthighfixedv2.stl</uri>
          </mesh>
        </geometry>
      </collision>
      <visual name='right_thigh_visual'>
        <pose>0 0 0 0 0 0</pose>
        <geometry>
          <mesh>
            <scale>0.001 0.001 0.001</scale>
            <uri>model://six_dof/meshes/rightthighfixedv2.stl</uri>
          </mesh>
        </geometry>
        <material>
          <diffuse>0 1 1 1</diffuse>
          <ambient>0 1 1 1</ambient>
        </material>
      </visual>
    </link>
    <joint name='right_thigh_shin' type='revolute'>
      <pose relative_to='right_thigh'>0.0025 -0.16 0 0 0 0</pose>
      <parent>right_thigh</parent>
      <child>right_shin</child>
      <axis>
        <xyz>1 0 0</xyz>
        <limit>
          <lower>-1.04</lower>
          <upper>1.04</upper>
          <effort>35</effort>
          <velocity>5.5</velocity>
        </limit>
        <dynamics>
          <damping>0.5</damping>
          <friction>0.69999999999999996</friction>
          <spring_reference>0</spring_reference>
          <spring_stiffness>0</spring_stiffness>
        </dynamics>
      </axis>
      <physics>
        <ode>
          <limit>
            <cfm>0</cfm>
            <erp>0.20000000000000001</erp>
          </limit>
        </ode>
      </physics>
      <joint>
        <dynamics damping='0.5' friction='0.7'/>
      </joint>
      <joint>
        <dynamics damping='0.5' friction='0.7'/>
      </joint>
    </joint>
    <link name='right_shin'>
      <pose relative_to='right_thigh_shin'>0 0 0 0 0 0</pose>
      <inertial>
        <pose>-0.02279 -0.05995 -6.999999999999999e-05 0 0 0</pose>
        <mass>0.014172000000000001</mass>
        <inertia>
          <ixx>0.0024608299999999998</ixx>
          <ixy>-1.6529999999999999e-05</ixy>
          <ixz>1.1999999999999999e-07</ixz>
          <iyy>0.00028524000000000003</iyy>
          <iyz>2.2999999999999999e-07</iyz>
          <izz>0.0027202900000000002</izz>
        </inertia>
      </inertial>
      <collision name='right_shin_collision'>
        <pose>0 0 0 0 0 0</pose>
        <geometry>
          <mesh>
            <scale>0.001 0.001 0.001</scale>
            <uri>model://six_dof/meshes/rightshinfixedv2.stl</uri>
          </mesh>
        </geometry>
      </collision>
      <visual name='right_shin_visual'>
        <pose>0 0 0 0 0 0</pose>
        <geometry>
          <mesh>
            <scale>0.001 0.001 0.001</scale>
            <uri>model://six_dof/meshes/rightshinfixedv2.stl</uri>
          </mesh>
        </geometry>
        <material>
          <diffuse>1 1 0 1</diffuse>
          <ambient>1 1 0 1</ambient>
        </material>
      </visual>
    </link>
    <joint name='right_shin_foot' type='revolute'>
      <pose relative_to='right_shin'>-0.02 -0.13 0 0 0 0</pose>
      <parent>right_shin</parent>
      <child>right_foot</child>
      <axis>
        <xyz>1 0 0</xyz>
        <limit>
          <lower>-0.52000000000000002</lower>
          <upper>0.52000000000000002</upper>
          <effort>35</effort>
          <velocity>5.5</velocity>
        </limit>
        <dynamics>
          <damping>0.69999999999999996</damping>
          <friction>1</friction>
          <spring_reference>0</spring_reference>
          <spring_stiffness>0</spring_stiffness>
        </dynamics>
      </axis>
      <physics>
        <ode>
          <limit>
            <cfm>0</cfm>
            <erp>0.20000000000000001</erp>
          </limit>
        </ode>
      </physics>
      <joint>
        <dynamics damping='0.7' friction='1.0'/>
      </joint>
    </joint>
    <link name='right_foot'>
      <pose relative_to='right_shin_foot'>0 0 0 0 0 0</pose>
      <inertial>
        <pose>-0.003 -0.011919 -9.8e-05 0 0 0</pose>
        <mass>0.022565999999999999</mass>
        <inertia>
          <ixx>9.6545799999999993e-06</ixx>
          <ixy>0</ixy>
          <ixz>3.0000000000000001e-12</ixz>
          <iyy>9.7001239999999995e-06</iyy>
          <iyz>7.7020799999999996e-07</iyz>
          <izz>1.471179e-06</izz>
        </inertia>
      </inertial>
      <collision name='right_foot_collision'>
        <pose>0 0 0 0 0 0</pose>
        <geometry>
          <mesh>
            <scale>0.001 0.001 0.001</scale>
            <uri>model://six_dof/meshes/footfixedv3.stl</uri>
          </mesh>
        </geometry>
      </collision>
      <visual name='right_foot_visual'>
        <pose>0 0 0 0 0 0</pose>
        <geometry>
          <mesh>
            <scale>0.001 0.001 0.001</scale>
            <uri>model://six_dof/meshes/footfixedv3.stl</uri>
          </mesh>
        </geometry>
        <material>
          <diffuse>0 1 0 1</diffuse>
          <ambient>0 1 0 1</ambient>
        </material>
      </visual>
    </link>
    <plugin name='ign_ros2_control::IgnitionROS2ControlPlugin' filename='ign_ros2_control-system'>
      <robot_param>robot_description</robot_param>
      <robot_param_node>robot_state_publisher</robot_param_node>
      <parameters>/home/adi/hum_rob_ws/src/six_dof_bringup/config/controller_config.yaml</parameters>
    </plugin>
    <frame name='base_body' attached_to='base_link'>
      <pose>0 0.05 0.3095 1.57 -0 0</pose>
    </frame>
    <frame name='body' attached_to='base_body'/>
  </model>
</sdf>
